Traceback (most recent call last):
  File "/home/josteines/src/SAR/my-book-files/SARbook/.venv/lib/python3.10/site-packages/jupyter_cache/executors/utils.py", line 58, in single_nb_execution
    executenb(
  File "/home/josteines/src/SAR/my-book-files/SARbook/.venv/lib/python3.10/site-packages/nbclient/client.py", line 1319, in execute
    return NotebookClient(nb=nb, resources=resources, km=km, **kwargs).execute()
  File "/home/josteines/src/SAR/my-book-files/SARbook/.venv/lib/python3.10/site-packages/jupyter_core/utils/__init__.py", line 165, in wrapped
    return loop.run_until_complete(inner)
  File "/usr/lib/python3.10/asyncio/base_events.py", line 649, in run_until_complete
    return future.result()
  File "/home/josteines/src/SAR/my-book-files/SARbook/.venv/lib/python3.10/site-packages/nbclient/client.py", line 709, in async_execute
    await self.async_execute_cell(
  File "/home/josteines/src/SAR/my-book-files/SARbook/.venv/lib/python3.10/site-packages/nbclient/client.py", line 1062, in async_execute_cell
    await self._check_raise_for_error(cell, cell_index, exec_reply)
  File "/home/josteines/src/SAR/my-book-files/SARbook/.venv/lib/python3.10/site-packages/nbclient/client.py", line 918, in _check_raise_for_error
    raise CellExecutionError.from_cell_and_msg(cell, exec_reply_content)
nbclient.exceptions.CellExecutionError: An error occurred while executing the following cell:
------------------
### Plotting the desired variable within its geographical extent 
  # - By default using the metadata for the geographical extent 
  # as lat/lon min/max values.

### Plotting geophysical_doppler
plotting_variables_on_a_map(
    ds = ds,
    variable = ds.geophysical_doppler,
    number_of_colorbar_intervals = 100,  # Default value
    title_fontsize = 15,                 # Default value
    cbar_label_fontsize = 12             # Default value
    )
------------------


[0;31m---------------------------------------------------------------------------[0m
[0;31mAttributeError[0m                            Traceback (most recent call last)
Cell [0;32mIn[7], line 8[0m
[1;32m      1[0m [38;5;66;03m### Plotting the desired variable within its geographical extent [39;00m
[1;32m      2[0m   [38;5;66;03m# - By default using the metadata for the geographical extent [39;00m
[1;32m      3[0m   [38;5;66;03m# as lat/lon min/max values.[39;00m
[1;32m      4[0m 
[1;32m      5[0m [38;5;66;03m### Plotting geophysical_doppler[39;00m
[1;32m      6[0m plotting_variables_on_a_map(
[1;32m      7[0m     ds [38;5;241m=[39m ds,
[0;32m----> 8[0m     variable [38;5;241m=[39m [43mds[49m[38;5;241;43m.[39;49m[43mgeophysical_doppler[49m,
[1;32m      9[0m     number_of_colorbar_intervals [38;5;241m=[39m [38;5;241m100[39m,  [38;5;66;03m# Default value[39;00m
[1;32m     10[0m     title_fontsize [38;5;241m=[39m [38;5;241m15[39m,                 [38;5;66;03m# Default value[39;00m
[1;32m     11[0m     cbar_label_fontsize [38;5;241m=[39m [38;5;241m12[39m             [38;5;66;03m# Default value[39;00m
[1;32m     12[0m     )

File [0;32m~/src/SAR/my-book-files/SARbook/.venv/lib/python3.10/site-packages/xarray/core/common.py:305[0m, in [0;36mAttrAccessMixin.__getattr__[0;34m(self, name)[0m
[1;32m    303[0m         [38;5;28;01mwith[39;00m suppress([38;5;167;01mKeyError[39;00m):
[1;32m    304[0m             [38;5;28;01mreturn[39;00m source[name]
[0;32m--> 305[0m [38;5;28;01mraise[39;00m [38;5;167;01mAttributeError[39;00m(
[1;32m    306[0m     [38;5;124mf[39m[38;5;124m"[39m[38;5;132;01m{[39;00m[38;5;28mtype[39m([38;5;28mself[39m)[38;5;241m.[39m[38;5;18m__name__[39m[38;5;132;01m!r}[39;00m[38;5;124m object has no attribute [39m[38;5;132;01m{[39;00mname[38;5;132;01m!r}[39;00m[38;5;124m"[39m
[1;32m    307[0m )

[0;31mAttributeError[0m: 'Dataset' object has no attribute 'geophysical_doppler'

